<?xml version="1.0" ?>
<!-- =================================================================================== -->
<!-- |    This document was autogenerated by xacro from /home/npd/Desktop/amr_bot/src/amr_description/urdf/amr.urdf.xacro | -->
<!-- |    EDITING THIS FILE BY HAND IS NOT RECOMMENDED                                 | -->
<!-- =================================================================================== -->
<robot name="amr_bot">
  <!-- Middle Drive Wheels -->
  <gazebo reference="wheel_left_link">
    <mu1>1000000000000000.0</mu1>
    <mu2>1000000000000000.0</mu2>
    <kp>1000000000000.0</kp>
    <kd>10.0</kd>
    <minDepth>0.001</minDepth>
    <maxVel>0.1</maxVel>
    <fdir1>1 0 0</fdir1>
  </gazebo>
  <gazebo reference="wheel_right_link">
    <mu1>1000000000000000.0</mu1>
    <mu2>1000000000000000.0</mu2>
    <kp>1000000000000.0</kp>
    <kd>10.0</kd>
    <minDepth>0.001</minDepth>
    <maxVel>0.1</maxVel>
    <fdir1>1 0 0</fdir1>
  </gazebo>
  <!-- Caster Wheels -->
  <gazebo reference="caster_wheel_front">
    <mu1>0.1</mu1>
    <mu2>0.1</mu2>
    <kp>1000000.0</kp>
    <kd>100.0</kd>
    <minDepth>0.001</minDepth>
    <maxVel>1.0</maxVel>
  </gazebo>
  <gazebo reference="caster_wheel_rear">
    <mu1>0.1</mu1>
    <mu2>0.1</mu2>
    <kp>1000000.0</kp>
    <kd>100.0</kd>
    <minDepth>0.001</minDepth>
    <maxVel>1.0</maxVel>
  </gazebo>
  <gazebo reference="caster1_wheel_front">
    <mu1>0.1</mu1>
    <mu2>0.1</mu2>
    <kp>1000000.0</kp>
    <kd>100.0</kd>
    <minDepth>0.001</minDepth>
    <maxVel>1.0</maxVel>
  </gazebo>
  <gazebo reference="caster2_wheel_rear">
    <mu1>0.1</mu1>
    <mu2>0.1</mu2>
    <kp>1000000.0</kp>
    <kd>100.0</kd>
    <minDepth>0.001</minDepth>
    <maxVel>1.0</maxVel>
  </gazebo>
  <!-- ROS 2 Control -->
  <gazebo>
    <plugin filename="libign_ros2_control-system.so" name="ign_ros2_control::IgnitionROS2ControlPlugin">
      <parameters>/home/npd/Desktop/amr_bot/install/amr_controller/share/amr_controller/config/amr_controllers.yaml</parameters>
    </plugin>
  </gazebo>
  <ros2_control name="RobotSystem" type="gazebo_ros2_control">
    <hardware>
      <plugin>ign_ros2_control/IgnitionSystem</plugin>
    </hardware>
    <joint name="wheel_right_joint">
      <command_interface name="velocity">
        <param name="min">-1</param>
        <param name="max">1</param>
      </command_interface>
      <state_interface name="position"/>
      <state_interface name="velocity"/>
      <state_interface name="effort"/>
    </joint>
    <joint name="wheel_left_joint">
      <command_interface name="velocity">
        <param name="min">-1</param>
        <param name="max">1</param>
      </command_interface>
      <state_interface name="position"/>
      <state_interface name="velocity"/>
      <state_interface name="effort"/>
    </joint>
  </ros2_control>
  <link name="base_footprint"/>
  <link name="base_link">
    <inertial>
      <!-- Slightly increase the mass for better stability -->
      <origin rpy="0.0 0.0 0.0" xyz="0 0 0.1"/>
      <mass value="1.2"/>
      <!-- Increased from 0.82573504 -->
      <inertia ixx="0.03" ixy="-0.0001" ixz="0.0003" iyy="0.03" iyz="-0.00005" izz="0.025"/>
    </inertial>
    <visual>
      <geometry>
        <box size="1.195 0.925 0.385"/>
        <!-- Slightly increased height for center of gravity -->
      </geometry>
      <origin rpy="0 0 0" xyz="0 0 0.1"/>
      <material name="Green">
        <color rgba="0 1 0 1"/>
        <!-- Green color (R,G,B,A) -->
      </material>
    </visual>
    <collision>
      <geometry>
        <box size="1.195 0.925 0.385"/>
      </geometry>
      <origin rpy="0 0 0" xyz="0 0 0.1"/>
    </collision>
  </link>
  <link name="lidar">
    <inertial>
      <origin rpy="0 0 0" xyz="0 0 0"/>
      <mass value="0.6"/>
      <!-- Slightly increased mass for stability -->
      <inertia ixx="0.0006" ixy="0" ixz="0" iyy="0.0006" iyz="0" izz="0.0006"/>
    </inertial>
    <visual>
      <geometry>
        <cylinder length="0.05" radius="0.1"/>
      </geometry>
      <material name="red">
        <color rgba="1 0 0 1"/>
      </material>
      <origin rpy="0 0 0" xyz="0 0 0.1"/>
    </visual>
    <collision>
      <geometry>
        <cylinder length="0.05" radius="0.1"/>
      </geometry>
      <origin rpy="0 0 0" xyz="0 0 0.1"/>
    </collision>
  </link>
  <link name="wheel_left_link">
    <inertial>
      <origin rpy="0 0 0" xyz="0 0 0"/>
      <mass value="0.065"/>
      <!-- Increased mass for wheels to improve control -->
      <inertia ixx="0.00002" ixy="0" ixz="0" iyy="0.00004" iyz="0" izz="0.00002"/>
    </inertial>
    <visual>
      <geometry>
        <cylinder length="0.06" radius="0.09"/>
        <!-- Slightly larger wheel for better grip -->
      </geometry>
      <origin rpy="1.57 0 0" xyz="0 0 0"/>
    </visual>
    <collision>
      <geometry>
        <cylinder length="0.05" radius="0.08"/>
      </geometry>
      <origin rpy="1.57 0 0" xyz="0 0 0"/>
    </collision>
  </link>
  <link name="wheel_right_link">
    <inertial>
      <origin rpy="0 0 0" xyz="0 0 0"/>
      <mass value="0.065"/>
      <!-- Match mass for left and right wheels -->
      <inertia ixx="0.00002" ixy="0" ixz="0" iyy="0.00004" iyz="0" izz="0.00002"/>
    </inertial>
    <visual>
      <geometry>
        <cylinder length="0.05" radius="0.08"/>
      </geometry>
      <origin rpy="-1.57 0 0" xyz="0 0 0"/>
    </visual>
    <collision>
      <geometry>
        <cylinder length="0.06" radius="0.09"/>
      </geometry>
      <origin rpy="-1.57 0 0" xyz="0 0 0"/>
    </collision>
  </link>
  <link name="caster_wheel_front">
    <inertial>
      <origin rpy="0 0 0" xyz="0 0 0"/>
      <mass value="0.00144379265037902"/>
      <inertia ixx="0.0000000000723075276010246" ixy="0" ixz="0" iyy="0.0000000000387137930859167" iyz="0" izz="0.000000000100967486676306"/>
    </inertial>
    <visual>
      <geometry>
        <cylinder length="0.05" radius="0.08"/>
      </geometry>
      <origin rpy="-1.57 0 0" xyz="0 0 0"/>
    </visual>
    <collision>
      <geometry>
        <sphere radius="0.08"/>
      </geometry>
      <origin rpy="0 0 0" xyz="0 0 0"/>
    </collision>
  </link>
  <link name="caster_wheel_rear">
    <inertial>
      <origin rpy="0 0 0" xyz="0 0 0"/>
      <mass value="0.00144379265037902"/>
      <inertia ixx="0.0000000000723075276010246" ixy="0" ixz="0" iyy="0.0000000000387137930859167" iyz="0" izz="0.000000000100967486676306"/>
    </inertial>
    <visual>
      <geometry>
        <cylinder length="0.05" radius="0.08"/>
      </geometry>
      <origin rpy="-1.57 0 0" xyz="0 0 0"/>
    </visual>
    <collision>
      <geometry>
        <sphere radius="0.08"/>
      </geometry>
      <origin rpy="0 0 0" xyz="0 0 0"/>
    </collision>
  </link>
  <link name="caster1_wheel_front">
    <inertial>
      <origin rpy="0 0 0" xyz="0 0 0"/>
      <mass value="0.00144379265037902"/>
      <inertia ixx="0.0000000000723075276010246" ixy="0" ixz="0" iyy="0.0000000000387137930859167" iyz="0" izz="0.000000000100967486676306"/>
    </inertial>
    <visual>
      <geometry>
        <cylinder length="0.05" radius="0.08"/>
      </geometry>
      <origin rpy="-1.57 0 0" xyz="0 0 0"/>
    </visual>
    <collision>
      <geometry>
        <sphere radius="0.05"/>
      </geometry>
      <origin rpy="0 0 0" xyz="0 0 0"/>
    </collision>
  </link>
  <link name="caster2_wheel_rear">
    <inertial>
      <origin rpy="0 0 0" xyz="0 0 0"/>
      <mass value="0.00144379265037902"/>
      <inertia ixx="0.0000000000723075276010246" ixy="0" ixz="0" iyy="0.0000000000387137930859167" iyz="0" izz="0.000000000100967486676306"/>
    </inertial>
    <visual>
      <geometry>
        <cylinder length="0.05" radius="0.08"/>
      </geometry>
      <origin rpy="-1.57 0 0" xyz="0 0 0"/>
    </visual>
    <collision>
      <geometry>
        <sphere radius="0.05"/>
      </geometry>
      <origin rpy="0 0 0" xyz="0 0 0"/>
    </collision>
  </link>
  <!-- Caster Wheels and other links remain unchanged -->
  <!-- Joints -->
  <joint name="base_joint" type="fixed">
    <parent link="base_footprint"/>
    <child link="base_link"/>
    <origin rpy="0 0 0" xyz="0 0 0.1"/>
  </joint>
  <joint name="base_lidar_joint" type="fixed">
    <parent link="base_link"/>
    <child link="lidar"/>
    <origin rpy="0 0 0" xyz="0 0 0.15"/>
  </joint>
  <!-- Fine-tuned joint parameters -->
  <joint name="wheel_right_joint" type="continuous">
    <parent link="base_link"/>
    <child link="wheel_right_link"/>
    <origin rpy="0 0 0" xyz="-0.05 0.34 -0.09"/>
    <!-- Increased distance for better stability -->
    <axis xyz="0 1 0"/>
  </joint>
  <joint name="wheel_left_joint" type="continuous">
    <parent link="base_link"/>
    <child link="wheel_left_link"/>
    <origin rpy="0 0 0" xyz="-0.05 -0.34 -0.09"/>
    <!-- Symmetrical adjustment -->
    <axis xyz="0 1 0"/>
  </joint>
  <!-- Rest of the caster wheel joints remain unchanged -->
  <joint name="front_caster_wheel_joint" type="fixed">
    <parent link="base_link"/>
    <child link="caster_wheel_front"/>
    <origin rpy="0 0 0" xyz="0.4 0.32 -0.09"/>
    <axis xyz="0 1 0"/>
  </joint>
  <joint name="rear_caster_wheel_joint" type="fixed">
    <parent link="base_link"/>
    <child link="caster_wheel_rear"/>
    <origin rpy="0 0 0" xyz="0.4 -0.32 -0.09"/>
    <axis xyz="0 1 0"/>
  </joint>
  <joint name="front_caster1_wheel_joint" type="fixed">
    <parent link="base_link"/>
    <child link="caster1_wheel_front"/>
    <origin rpy="0 0 0" xyz="-0.4 -0.32 -0.09"/>
    <axis xyz="0 1 0"/>
  </joint>
  <joint name="rear_caster2_wheel_joint" type="fixed">
    <parent link="base_link"/>
    <child link="caster2_wheel_rear"/>
    <origin rpy="0 0 0" xyz="-0.4 0.32 -0.09"/>
    <axis xyz="0 1 0"/>
  </joint>
</robot>
